# 异常处理 Exception Handling
本篇记录了异常处理的基本知识点

### 什么是异常处理？
异常处理`Exception Handling`是一种机制，用来处理程序中出现的异常情况，即超出程序正常执行的一些特殊条件。

### 为什么要异常处理？
两个原因，分别是：
1. 异常情况会直接导致程序崩溃，然后我们只知道潜在出错的地方但不知道具体错误出在哪里
2. 有时候系统抛出异常后我们并不想让程序终止，而想让程序执行一个替代方法，这个时候我们就需要异常处理机制

如，在除法中分母不能为零，倘若我们给分母赋值为`0`，则程序会崩溃，并抛出异常。代码如下：
```c#
public class Div  
{
  public int Divide(int n1, int n2)  //定义一个基本的除法
  {
    return n1 / n2;
  }
}

static void Main(string[] args)
{
  Console.WriteLine(Divide(5, 0));  //打印出5除以0的结果
}
```

这个时候控制台会抛出异常，并终止程序。在控制台中我们可以看到未能处理的异常：
```
Unhandle Exception: System.DivideByZeroException: Attempted to divide by zero.
```
我们可以看出抛出的异常也是一个类，为在`System`命名空间中的`DivideByZeroException`类。我们还会看到控制台按顺序指出哪个参数、哪个方法、哪个类、哪个命名空间、哪个文件中的哪一行出了问题。这个过程叫做栈追踪`Stack Trace`，通过反向追踪函数调用轨迹来查找出问题的部分。

如果没有异常处理，即出现`Unhandle Exception`的情况，系统会调用终止函数来让整个程序强制结束，即俗称程序崩溃。

### 如何处理异常？
使用`try``catch`代码块，即如果在`try`的代码块中抛出异常，那么直接执行`catch`代码块的命令。在`catch中`，我们可以选择直接抛出异常，给出一些更有实际意义的报错语句，或把异常作为内部异常，使用一个新的自定义异常类重新抛出异常。继续以以上为例直接抛出异常，不过换个用户友好的表达：
```c#
static void Main(string[] args)
{
  try
  {
    Console.WriteLine(Divide(5, 0));  //打印出5除以0的结果，此处会抛出DivideByZeroException异常
  }
  catch(Exception)
  {
    Console.WriteLine("Sorry, we cannot divide by 0.");
  }
}
```
以上运行结果仅为一条`"Sorry, we cannot divide by 0."`，这样反馈更有可读性，没有复杂的`Stack Trace`结果，并且程序不会崩溃。

### catch 中的 Exception 是什么？
异常`Exception`也是所有异常类的基类，`catch`块需要访问一个异常类，这个类的成员记录了所有相关的异常信息，如`Message`记录了异常描述，`Source`记录了产生异常的应用名（程序集或`dll`），`StackTrace`记录了调用方法的反向轨迹，`TargetSite`记录了抛出异常的方法等等。

我们可以很容易调用这些信息，如：
```c#
  catch(Exception e)
  {
    Console.WriteLine(e.Message);
    Console.WriteLine(e.Source);
    Console.WriteLine(e.StackTrace);
  }
```

除了以上四个常用的属性，此外还有`InnerException`记录了被插入到这个异常中的其他异常，稍后会详细讨论。

在某些情况下，一个代码块可能会抛出多种不同的异常，这个时候我们就需要多重`catch`块来对异常进行匹配，匹配到的第一个`catch`代码块将被执行，其他`catch`块将不被执行，并且`catch`块的顺序必须由具体到泛型，如：
```c#
static void Main(string[] args)
{
  try
  {
    Console.WriteLine(Divide(5, 0));  //打印出5除以0的结果
  }
  catch(DivideByZeroException e)  //最具体的类，其父类为 ArithmeticException
  {
    Console.WriteLine("Sorry, we cannot divide by 0.");
  }
  catch(ArithmeticException e)  //其父类为SystemException
  {
    Console.WriteLine("Sorry, we cannot divide by 0.");
  }
  catch(SystemException e)  //其父类为Exception
  {
    Console.WriteLine("Sorry, we cannot divide by 0.");
  }
    catch(Exception e)  //所有异常类的基类
  {
    Console.WriteLine("Sorry, we cannot divide by 0.");
  }
}
```

此外，还有一种`finally`块。在很多实际情况中`.NET`有时候需要访问一些非托管资源`Unmanaged Resources`，即非CLR托管的资源，如文件系统操作、数据库连接、网络连接等，在访问这些资源后我们需要手动释放清理。任何访问这些非托管资源的类都应该有`IDisposable`接口。

### 什么是IDisposable接口？
`IDisposable`接口中只有一个方法`Dispose()`，即释放分配的资源的方法，我们需要在`finally`块中调用这个接口来实现资源的释放。以文件系统读取为例：
```c#
static void Main(string[] args)
{
  StreamReader streamBreader;
  try
  {
    streamReader = new StreamReader(@"c:\file.zip");  //读取路径文件
    var content = stramReader.ReadToEnd();  //如果这个地方抛出异常，除了执行catch块，还会执行finally块
  }
  catch (Exception e)
  {
    Console.Writeline("发生了异常");  
  }
  finally   //无论是否抛出异常，这个代码块的内容总被执行
  {
    if(stramReader != null)
      streamReader.Dispose();  //执行释放空间方法
  }
}
```

关于`finally`代码块，必须知道的是有一种替代的简写，即使用关键词`using`。这个关键词定义了一个使用范围，即当实例对象被销毁或取消后（通常是因为抛出异常）会自动添加一个`finally`块并调用`Dispose()`释放资源，无需手动再写`finally`块。代码如下：
```c#
static void Main(string[] args)
{
  try
  {
    using(var streamReader = new StreamReader(@"c:\file.zip"))    //意为“我现在使用这个实例，并将监视它。如果它不见了，我要自动执行finally块”
    {
          var content = stramReader.ReadToEnd();
    }
  }
  catch (Exception e)
  {
    Console.Writeline("发生了异常");  
  }
  //会自动添加finally代码块并调用streaReader.Depose()方法。
}
```

### 如何定制异常？为什么我们需要定制异常？
在很多情况下，一个代码块抛出的异常可能发生在低层，我们可能并不想把这些低层异常暴露给在程序的高层，即不想告诉`Exception`发生了什么，想在它知晓以前用自己的方式处理异常，即之前说的使用一个新的自定义异常类重新抛出异常，这种情况下我们就需要定制异常。

举一个`Youtube`上传文件失败的异常，我们不想让`Expection`来处理，看起来乱，而使用自定义`YoutubeExpection`来擦除`Exception`的异常信息，抛出可读性更强的异常。代码如下：
```c#
public class YoutubeException : Exception   //必须基于Exception来派生自定义类
{
  //基于Exception原有的构造函数来构造函数
  public YoutubeException(string message, Exception innerException)
    :base(message, innerException)
  {
  }
}

public class YoutubeApi
{
  public List<Video> GetVideos(string user)
  {
    try
    {
      //Access Youtube web service
      //Read ....
      //Creat ....
      throw new Exception("Some lower level error");    //手动模拟抛出异常
    }
    catch(Exception ex)
    {
      throw new YoutubeException("Sorry, uploading failed", ex);    //使用定制异常擦除原Exception异常信息
    }
    return new List<Video>();
  }
}

static void Main(string[] args)
{
  try
  {
    var api = new YoutubeApi();
    var videos = api.GetVideos("sdw");  //这里必定抛出异常
  }
  catch(Exception ex)
  {
    Console.WriteLine(ex.Message);    //这个时候Exception的message已经被擦除成YoutubeException的异常信息了，
  }
}//运行程序，抛出的是擦除后的异常信息。原信息储存在 ex.InnerException 中。
```

`InnerException`是一个很重要的属性，在很多实际情况中，如`Entity Framwork`，我们通过查看`ex`的`InnerException`来获知问题的源头。

### 异常处理的`try``catch`块一般写在哪？
一般写程序的入口处，如主函数，事件处理函数，线程入口处。不能在构造函数处使用异常处理，这里并不能处理，反而会抛出新的异常。

暂时想到这么多，最后更新2017/11/17

最后更新2018/05/14
